<?xml version="1.0"?>
<robot name="dd_robot">

    <!-- Base Link-->
    <link name="base_link">
        <visual>
            <origin xyz="0.0 0.0 0.0575" rpy="0.0 0.0 0.0"/>
            <geometry>
                <cylinder radius="0.175" length="0.089"/>
            </geometry>
            <material name="blue">
                <color rgba="0.0 0.5 1.0 1.0"/>
            </material>
        </visual>
        
        <inertial>
            <mass value="2.2"/>
            <inertia ixx="0.0182959" ixy="0.0" ixz="0.0" 
                     iyy="0.0182959" iyz="0.0" izz="0.0336875"/>
        </inertial>
        

        <!-- Base collision-->
        <collision>
            <origin xyz="0.0 0.0 0.0575" rpy="0.0 0.0 0.0"/>
            <geometry>
                <cylinder radius="0.175" length="0.089"/>
            </geometry>
        </collision>


        <!-- Casters-->
        <visual name="front_wheel">
            <origin xyz="0.115 0.0 0.017" rpy="1.570735 0.0 0.0"/>
            <geometry>
                <cylinder radius="0.017" length="0.01"/>
            </geometry>
            <material name="black">
                <color rgba="0.05 0.05 0.05 1.0"/>
                <texture filename=""/>
            </material>
        </visual>

        <inertial>
            <mass value="0.025"/>
            <inertia ixx="0.000002014" ixy="0.0" ixz="0.0" 
                     iyy="0.0000036125" iyz="0.0" izz="0.000002014"/>
        </inertial>
        

        <visual name="back_wheel">
            <origin xyz="-0.115 0.0 0.017" rpy="1.570795 0.0 0.0"/>
            <geometry>
                <cylinder radius="0.017" length="0.01"/>
            </geometry>
            <material name="black" />
        </visual>

        <inertial>
            <mass value="0.025"/>
            <inertia ixx="0.000002014" ixy="0.0" ixz="0.0" 
                     iyy="0.0000036125" iyz="0.0" izz="0.000002014"/>
        </inertial>

        <!-- Casters collision-->
        <collision>
            <origin xyz="0.115 0.0 0.017" rpy="1.570735 0.0 0.0"/>
            <geometry>
                <cylinder radius="0.017" length="0.01"/>
            </geometry>
        </collision>

        <collision>
            <origin xyz="-0.115 0.0 0.017" rpy="1.570795 0.0 0.0"/>
            <geometry>
                <cylinder radius="0.017" length="0.01"/>
            </geometry>
        </collision>
    </link>

    <!-- Right Wheel-->
    <link name="right_wheel">
        <visual>
            <origin xyz="0.0 0.0 0.0" rpy="1.570795 0.0 0.0"/>
            <geometry>
                <cylinder radius="0.0342" length="0.02"/>
            </geometry>
            <material name="black" />
        </visual>

        <inertial>
            <mass value="0.05"/>
            <inertia ixx="0.0000167179" ixy="0.0" ixz="0.0" 
                     iyy="0.000029241" iyz="0.0" izz="0.0000167179"/>
        </inertial>

        <!-- Right Wheel collision-->
        <collision>
            <origin xyz="0.0 0.0 0.0" rpy="1.570795 0.0 0.0"/>
            <geometry>
                <cylinder radius="0.0342" length="0.02"/>
            </geometry>
        </collision>
    </link>

    <joint name="joint_right_wheel" type="continuous">
        <parent link="base_link"/>
        <child link="right_wheel"/>
        <origin xyz="0.0 -0.117539 0.03423" rpy="0.0 0.0 0.0"/>
        <axis xyz="0.0 1.0 0.0"/>  
        <limit effort="10" velocity="6.0"/>      
    </joint>

    <transmission name="tranmission_1">
        <type>transmission_interface/SimpleTransmission</type>
        <joint name="joint_right_wheel">
            <hardwareInterface>hardware_interface/VelocityJointInterface</hardwareInterface>
        </joint>
        <actuator name="right_motor">
            <mechanicalReduction>1</mechanicalReduction>
        </actuator>
    </transmission>

    <!-- Left Wheel-->
    <link name="left_wheel">
        <visual>
            <origin xyz="0.0 0.0 0.0" rpy="1.570795 0.0 0.0"/>
            <geometry>
                <cylinder radius="0.0342" length="0.02"/>
            </geometry>
            <material name="black" />
        </visual>

        <inertial>
            <mass value="0.05"/>
            <inertia ixx="0.0000167179" ixy="0.0" ixz="0.0" 
                     iyy="0.000029241" iyz="0.0" izz="0.0000167179"/>
        </inertial>

        <!-- Left Wheel collision-->
        <collision>
            <origin xyz="0.0 0.0 0.0" rpy="1.570795 0.0 0.0"/>
            <geometry>
                <cylinder radius="0.0342" length="0.02"/>
            </geometry>
        </collision>
    </link>

    <joint name="joint_left_wheel" type="continuous">
        <parent link="base_link"/>
        <child link="left_wheel"/>
        <origin xyz="0.0 0.117539 0.03423" rpy="0.0 0.0 0.0"/>
        <axis xyz="0.0 1.0 0.0"/>    
        <limit effort="10" velocity="6.0"/>    
    </joint>
    
    <transmission name="tranmission_2">
        <type>transmission_interface/SimpleTransmission</type>
        <joint name="joint_left_wheel">
            <hardwareInterface>hardware_interface/VelocityJointInterface</hardwareInterface>
        </joint>
        <actuator name="left_motor">
            <mechanicalReduction>1</mechanicalReduction>
        </actuator>
    </transmission>

    <!-- Gazebo ROS Plugin-->
    <!-- Plugin para que Gazebo pueda entender los controladores-->
    <gazebo>
        <plugin name="gazebo_ros_control" filename="libgazebo_ros_control.so">
            <robotNamespace>/</robotNamespace>
        </plugin>
    </gazebo>

</robot>